Workbook

Sheet Model
A1: Levitating chess coil-density model
A3: Design inputs
A4: Input | B4: Magnet cube edge (s) | C4: 3 | D4: mm | E4: cube edge; height = edge; pole pitch = magnets x edge
A5: Input | B5: Magnets per pole | C5: 2 | E5: cube-buildable Halbach, 90 deg magnetization steps
A6: Input | B6: Poles per side | C6: 4 | D6: poles | E6: Halbach poles across one platform side
A7: Input | B7: Magnet-to-coil distance | C7: 3 | D7: mm
A8: Input | B8: Plastic wall thickness | C8: 1.5 | D8: mm | E8: 3D-printed hollow shell wall
A9: Input | B9: DC bus voltage | C9: 5 | D9: V
A10: Input | B10: Max current per winding | C10: 0.03 | D10: A
A11: Input | B11: Move pulse duration | C11: 10 | D11: s
A12: Input | B12: Allowed wire temp rise after pulse | C12: 40 | D12: C
A13: Input | B13: Force safety factor | C13: 1.3 | D13: x | E13: Required force = piece weight * SF
A14: Input | B14: Control loop bandwidth margin | C14: 5 | D14: x | E14: loop must be this many times faster than the instability
A15: Input | B15: Pieces levitating simultaneously (worst case) | C15: 32 | D15: pieces | E15: all pieces moving at once (e.g. reset) = worst case
A16: Input | B16: Sense look-ahead factor | C16: 1.5 | D16: x | E16: extra coils scanned around each piece to track motion
A18: Fixed parameters
A19: Fixed | B19: Base material clearance around Halbach | C19: 1 | D19: mm | E19: Added to round base diameter
A20: Fixed | B20: Square fill ratio | C20: 0.8 | E20: Round base / square size
A21: Fixed | B21: Captured pieces total | C21: 32 | D21: pieces | E21: Side storage capacity
A22: Fixed | B22: Captured side areas | C22: 2 | D22: areas | E22: Left/right
A23: Fixed | B23: Captured packing efficiency | C23: 0.9 | E23: Tight side storage
A24: Fixed | B24: Herringbone orientation families | C24: 2 | E24: two coil directions for planar (x,y) force
A25: Fixed | B25: Halbach first-harmonic coefficient | C25: 0.65 | E25: Simplified first harmonic
A26: Fixed | B26: Reference king height | C26: 95 | D26: mm | E26: standard king height
A27: Fixed | B27: Reference king base diameter | C27: 44 | D27: mm | E27: standard king base
A28: Fixed | B28: Wire enamel outside factor | C28: 1.08
A29: Fixed | B29: Coil aspect ratio L/W (target) | C29: 2.5 | E29: used only to pick how many coils tile the platform length
A30: Fixed | B30: Winding radial width factor | C30: 0.35 | E30: x coil outer width
A31: Fixed | B31: Force straight-length efficiency | C31: 0.65 | E31: Phase/fringe allowance
A32: Fixed | B32: LED/current sink channels per chip | C32: 16 | D32: channels
A33: Fixed | B33: Usable bus voltage fraction | C33: 0.9 | E33: Headroom for driver losses
A34: Fixed | B34: LDC1614 sample rate per channel | C34: 4000 | D34: sps | E34: datasheet config-dependent
A35: Fixed | B35: Coils per sense channel (mux 16:1) | C35: 16 | D35: coils | E35: CD74HC4067 time-shares this many coils on one channel
A36: Constants
A37: Constant | B37: Board squares per side | C37: 8 | E37: chess board is 8x8
A38: Constant | B38: NdFeB remanence Br | C38: 1.24 | D38: T
A39: Constant | B39: NdFeB density | C39: 0.0075 | D39: g/mm3
A40: Constant | B40: Plastic density | C40: 0.0012 | D40: g/mm3 | E40: typical 3D-print plastic (g/cm3 scale)
A41: Constant | B41: Copper resistivity | C41: 1.724e-08 | D41: ohm.m
A42: Constant | B42: Copper density | C42: 8960 | D42: kg/m3
...

Sheet Options
A1: Component alternates (Digikey qty ~1k, USD). Pick one per category.
A3: Coil driver IC (chosen: TLC59283DBQR)
A4: MPN | B4: Ch | C4: Unit $ | D4: Qty | E4: Note | F4: Link
A5: TLC59283DBQR | B5: 16 | C5: 0.373 | D5: =Model!C73 | E5: Chosen; LED sink, needs external flyback | F5: =HYPERLINK("https://www.digikey.com/en/products/result?keywords=TLC59283DBQR","Digikey: TLC59283DBQR")
A6: TLC5928DBQR | B6: 16 | D6: =Model!C73 | E6: Higher-accuracy current sink | F6: =HYPERLINK("https://www.digikey.com/en/products/result?keywords=TLC5928DBQR","Digikey: TLC5928DBQR")
A7: STP16CP05XTTR | B7: 16 | D7: =Model!C73 | E7: Higher current capability | F7: =HYPERLINK("https://www.digikey.com/en/products/result?keywords=STP16CP05XTTR","Digikey: STP16CP05XTTR")
A8: TPIC6C596DR | B8: 8 | C8: 0.85 | D8: =Model!C72/8 | E8: DMOS, internal flyback, ~2x chip count | F8: =HYPERLINK("https://www.digikey.com/en/products/result?keywords=TPIC6C596DR","Digikey: TPIC6C596DR")
A9: ULN2803ADWR | B9: 8 | C9: 0.3 | D9: =Model!C72/8 | E9: Cheap but 0.9 V drop; not viable at 5 V | F9: =HYPERLINK("https://www.digikey.com/en/products/result?keywords=ULN2803ADWR","Digikey: ULN2803ADWR")
A11: Flyback diode (qty = one per driver output; only if driver lacks clamp)
A12: MPN | B12: Type | C12: Vf | D12: Unit $ | E12: Note | F12: Link
A13: 1N4148WS-7-F | B13: Si fast | C13: 1.0 V | D13: 0.04 | E13: Chosen; SOD-323 | F13: =HYPERLINK("https://www.digikey.com/en/products/result?keywords=1N4148WS-7-F","Digikey: 1N4148WS-7-F")
A14: BAT54XV2T1G | B14: Schottky | C14: 0.35 V | D14: 0.06 | E14: Lower Vf | F14: =HYPERLINK("https://www.digikey.com/en/products/result?keywords=BAT54XV2T1G","Digikey: BAT54XV2T1G")
A15: BAT30KFILM | B15: Schottky | C15: 0.30 V | D15: 0.091 | E15: Lowest Vf | F15: =HYPERLINK("https://www.digikey.com/en/products/result?keywords=BAT30KFILM","Digikey: BAT30KFILM")
A17: Magnet wire source (chosen: QA-1-155 0.05 mm)
A18: Source | B18: Qty | C18: Unit $ | D18: Total $ | E18: Note | F18: Link
A19: QA-1-155 0.05 mm, 1 kg (AE 4000274595791) | B19: =CEILING(Model!C127,1) | C19: 43 | D19: =B19*C19 | E19: Chosen; ~44 AWG, 1 kg spool | F19: =HYPERLINK("https://fr.aliexpress.com/item/4000274595791.html","Aliexpress item")
A20: 44SNSP.25 (Digikey) | B20: =CEILING(Model!C126/6081,1) | C20: 18 | D20: =B20*C20 | E20: Backup; Digikey stock, fast shipping | F20: =HYPERLINK("https://www.digikey.com/en/products/result?keywords=44SNSP.25","Digikey: 44SNSP.25")
A21: MWS Wire (custom) | B21: ~5 | C21: 80 | D21: ~400 | E21: Premium MIL-spec; quote required | F21: =HYPERLINK("https://www.mwswire.com/","MWS Wire")
A26: Standard magnet wire bare diameters (mm) - used by Model wire auto-select
A27: 0.03
A28: 0.04
A29: 0.05
A30: 0.063
A31: 0.071
A32: 0.08
A33: 0.09
A34: 0.1
A35: 0.112
A36: 0.125
A37: 0.14
A38: 0.16
A40: Standard magnet cube edge sizes (mm) - reference for the magnet cube edge input
A41: 0.5
A42: 1
A43: 1.5
A44: 2
A45: 2.5
A46: 3
A47: 3.5
A48: 4
...
